<?xml version="1.0" encoding="utf-8"?>
<robot
  name="BD-5">
  <link
    name="BODY">
    <inertial>
      <origin
        xyz="-0.22E-3 0.78E-3 8.59E-3"
        rpy="0 0 0" />
      <mass
        value="0.72699" />
      <inertia
        ixx="1.31183269E-03"
        ixy="3.70409700E-05"
        ixz="1.32161000E-06"
        iyy="2.29445038E-03"
        iyz="-1.00278300E-05"
        izz="1.96937299E-03" />
    </inertial>
    <visual>
      <origin
        xyz="0 0 0"
        rpy="0 0 0" />
      <geometry>
        <mesh
          filename="/home/master/Bureau/BD-5/description/BD-5/meshes/BODY.STL" />
      </geometry>
      <material
        name="">
        <color
          rgba="0.9098 0.44314 0.031373 1" />
      </material>
    </visual>
    <collision>
      <origin
        xyz="0 0 0"
        rpy="0 0 0" />
      <geometry>
        <mesh
          filename="/home/master/Bureau/BD-5/description/BD-5/meshes/BODY.STL" />
      </geometry>
    </collision>
  </link>
  <link
    name="NECK">
    <inertial>
      <origin
        xyz="0 1.70E-03 35.48E-03"
        rpy="0 0 0" />
      <mass
        value="0.019" />
      <inertia
        ixx="1.60230E-05"
        ixy="0.0"
        ixz="0.0"
        iyy="9.81822E-06"
        iyz="0.0"
        izz="7.80181E-06" />
    </inertial>
    <visual>
      <origin
        xyz="0 0 0"
        rpy="0 0 0" />
      <geometry>
        <mesh
          filename="/home/master/Bureau/BD-5/description/BD-5/meshes/NECK.STL" />
      </geometry>
      <material
        name="">
        <color
          rgba="0.25098 0.25098 0.25098 1" />
      </material>
    </visual>
    <collision>
      <origin
        xyz="0 0 0"
        rpy="0 0 0" />
      <geometry>
        <mesh
          filename="/home/master/Bureau/BD-5/description/BD-5/meshes/NECK.STL" />
      </geometry>
    </collision>
  </link>
  <joint
    name="neck_pitch"
    type="fixed">
    <origin
      xyz="0.039 -0.0017032 0.06245"
      rpy="0 -0.52482 0" />
    <parent
      link="BODY" />
    <child
      link="NECK" />
    <axis
      xyz="0 0 0" />
  </joint>
  <link
    name="HEAD">
    <inertial>
      <origin
        xyz="-0.33E-3 2.75E-03 20.66E-03"
        rpy="0 0 0" />
      <mass
        value="0.17460" />
      <inertia
        ixx="3.2166268E-04"
        ixy="1.2352400E-06"
        ixz="-1.7300220E-05"
        iyy="4.2251228E-04"
        iyz="-3.5853500E-06"
        izz="6.7423500E-04" />
    </inertial>
    <visual>
      <origin
        xyz="0 0 0"
        rpy="0 0 0" />
      <geometry>
        <mesh
          filename="/home/master/Bureau/BD-5/description/BD-5/meshes/HEAD.STL" />
      </geometry>
      <material
        name="">
        <color
          rgba="0.9098 0.44314 0.031373 1" />
      </material>
    </visual>
    <collision>
      <origin
        xyz="0 0 0"
        rpy="0 0 0" />
      <geometry>
        <mesh
          filename="/home/master/Bureau/BD-5/description/BD-5/meshes/HEAD.STL" />
      </geometry>
    </collision>
  </link>
  <joint
    name="head_pitch"
    type="fixed">
    <origin
      xyz="0 0 0.082"
      rpy="0 0.52804 0" />
    <parent
      link="NECK" />
    <child
      link="HEAD" />
    <axis
      xyz="0 0 0" />
  </joint>
  <link
    name="HIP_LEFT">
    <inertial>
      <origin
        xyz="1.85E-03 52.84E-03 27.86E-03"
        rpy="0 0 0" />
      <mass
        value="0.101" />
      <inertia
        ixx="4.153369E-05"
        ixy="-2.214420E-06"
        ixz="3.279540E-06"
        iyy="4.405694E-05"
        iyz="-1.604100E-07"
        izz="2.979343E-05" />
    </inertial>
    <visual>
      <origin
        xyz="0 0 0"
        rpy="0 0 0" />
      <geometry>
        <mesh
          filename="/home/master/Bureau/BD-5/description/BD-5/meshes/HIP_LEFT.STL" />
      </geometry>
      <material
        name="">
        <color
          rgba="0.25098 0.25098 0.25098 1" />
      </material>
    </visual>
    <collision>
      <origin
        xyz="0 0 0"
        rpy="0 0 0" />
      <geometry>
        <mesh
          filename="/home/master/Bureau/BD-5/description/BD-5/meshes/HIP_LEFT.STL" />
      </geometry>
    </collision>
  </link>
  <joint
    name="left_hip_yaw"
    type="revolute">
    <origin
      xyz="0 0.01425 -0.0436"
      rpy="0 0 0" />
    <parent
      link="BODY" />
    <child
      link="HIP_LEFT" />
    <axis
      xyz="0 0 1" />
    <limit
      lower="-0.37899"
      upper="0.37899"
      effort="41"
      velocity="4.8171" />
    <dynamics
      damping="1.084"
      friction="0.03" />
    <safety_controller
      k_position="21.1"
      k_velocity="0" />
  </joint>
  <link
    name="HIP_R_LEFT">
    <inertial>
      <origin
        xyz="0 0 -25.15E-03"
        rpy="0 0 0" />
      <mass
        value="0.018" />
      <inertia
        ixx="6.25751E-06"
        ixy="-2.00000E-11"
        ixz="0.0"
        iyy="5.92983E-06"
        iyz="0.0"
        izz="7.87081E-06" />
    </inertial>
    <visual>
      <origin
        xyz="0 0 0"
        rpy="0 0 0" />
      <geometry>
        <mesh
          filename="/home/master/Bureau/BD-5/description/BD-5/meshes/HIP_R_LEFT.STL" />
      </geometry>
      <material
        name="">
        <color
          rgba="0.25098 0.25098 0.25098 1" />
      </material>
    </visual>
    <collision>
      <origin
        xyz="0 0 0"
        rpy="0 0 0" />
      <geometry>
        <mesh
          filename="/home/master/Bureau/BD-5/description/BD-5/meshes/HIP_R_LEFT.STL" />
      </geometry>
    </collision>
  </link>
  <joint
    name="left_hip_roll"
    type="revolute">
    <origin
      xyz="0 0.05925 0.01275"
      rpy="0 0 0" />
    <parent
      link="HIP_LEFT" />
    <child
      link="HIP_R_LEFT" />
    <axis
      xyz="-1 0 0" />
    <limit
      lower="-1.8827"
      upper="0.38819"
      effort="41"
      velocity="4.8171" />
    <dynamics
      damping="1.084"
      friction="0.03" />
    <safety_controller
      k_position="21.1"
      k_velocity="0" />
  </joint>
  <link
    name="THIGH_LEFT">
    <inertial>
      <origin
        xyz="0 2.15E-03 -35.25E-03"
        rpy="0 0 0" />
      <mass
        value="0.174" />
      <inertia
        ixx="1.1144779E-04"
        ixy="0.0"
        ixz="-5.9978000e-07"
        iyy="9.3367670E-05"
        iyz="0.0"
        izz="5.1193580E-05" />
    </inertial>
    <visual>
      <origin
        xyz="0 0 0"
        rpy="0 0 0" />
      <geometry>
        <mesh
          filename="/home/master/Bureau/BD-5/description/BD-5/meshes/THIGH_LEFT.STL" />
      </geometry>
      <material
        name="">
        <color
          rgba="0.25098 0.25098 0.25098 1" />
      </material>
    </visual>
    <collision>
      <origin
        xyz="0 0 0"
        rpy="0 0 0" />
      <geometry>
        <mesh
          filename="/home/master/Bureau/BD-5/description/BD-5/meshes/THIGH_LEFT.STL" />
      </geometry>
    </collision>
  </link>
  <joint
    name="left_hip_pitch"
    type="revolute">
    <origin
      xyz="0 0 -0.05"
      rpy="0 0 0" />
    <parent
      link="HIP_R_LEFT" />
    <child
      link="THIGH_LEFT" />
    <axis
      xyz="0 1 0" />
    <limit
      lower="-1.7492"
      upper="1.7492"
      effort="41"
      velocity="4.8171" />
    <dynamics
      damping="1.084"
      friction="0.03" />
    <safety_controller
      k_position="21.1"
      k_velocity="0" />
  </joint>
  <link
    name="CALF_LEFT">
    <inertial>
      <origin
        xyz="0.34E-03 1.91E-03 -50.36E-03"
        rpy="0 0 0" />
      <mass
        value="0.098" />
      <inertia
        ixx="4.467074E-05"
        ixy="-2.144200E-06"
        ixz="1.998000E-07"
        iyy="3.067445E-05"
        iyz="3.182100E-06"
        izz="3.166172E-05" />
    </inertial>
    <visual>
      <origin
        xyz="0 0 0"
        rpy="0 0 0" />
      <geometry>
        <mesh
          filename="/home/master/Bureau/BD-5/description/BD-5/meshes/CALF_LEFT.STL" />
      </geometry>
      <material
        name="">
        <color
          rgba="0.25098 0.25098 0.25098 1" />
      </material>
    </visual>
    <collision>
      <origin
        xyz="0 0 0"
        rpy="0 0 0" />
      <geometry>
        <mesh
          filename="/home/master/Bureau/BD-5/description/BD-5/meshes/CALF_LEFT.STL" />
      </geometry>
    </collision>
  </link>
  <joint
    name="left_knee"
    type="revolute">
    <origin
      xyz="0 0 -0.0705"
      rpy="0 0 0" />
    <parent
      link="THIGH_LEFT" />
    <child
      link="CALF_LEFT" />
    <axis
      xyz="0 -1 0" />
    <limit
      lower="0"
      upper="2.3829"
      effort="41"
      velocity="4.8171" />
    <dynamics
      damping="1.084"
      friction="0.03" />
    <safety_controller
      k_position="21.1"
      k_velocity="0" />
  </joint>
  <link
    name="FOOT_LEFT">
    <inertial>
      <origin
        xyz="0 0 -33.34E-03"
        rpy="0 0 0" />
      <mass
        value="0.032" />
      <inertia
        ixx="6.903700E-06"
        ixy="0.0"
        ixz="0.0"
        iyy="3.164244e-05"
        iyz="0.0"
        izz="3.174429e-05" />
    </inertial>
    <visual>
      <origin
        xyz="0 0 0"
        rpy="0 0 0" />
      <geometry>
        <mesh
          filename="/home/master/Bureau/BD-5/description/BD-5/meshes/FOOT_LEFT.STL" />
      </geometry>
      <material
        name="">
        <color
          rgba="0.9098 0.44314 0.031373 1" />
      </material>
    </visual>
    <collision>
      <origin
        xyz="0 0 0"
        rpy="0 0 0" />
      <geometry>
        <mesh
          filename="/home/master/Bureau/BD-5/description/BD-5/meshes/FOOT_LEFT.STL" />
      </geometry>
    </collision>
  </link>
  <joint
    name="left_ankle"
    type="revolute">
    <origin
      xyz="0 0 -0.07064"
      rpy="0 0 0" />
    <parent
      link="CALF_LEFT" />
    <child
      link="FOOT_LEFT" />
    <axis
      xyz="0 1 0" />
    <limit
      lower="-1.8873"
      upper="1.8873"
      effort="41"
      velocity="4.8171" />
    <dynamics
      damping="1.084"
      friction="0.03" />
    <safety_controller
      k_position="21.1"
      k_velocity="0" />
  </joint>
  <link
    name="HIP_RIGHT">
    <inertial>
      <origin
        xyz="1.85E-03 -53.5E-03 27.86E-03"
        rpy="0 0 0" />
      <mass
        value="0.101" />
      <inertia
        ixx="4.234531E-05"
        ixy="-1.005060E-06"
        ixz="2.214420E-06"
        iyy="2.979343E-05"
        iyz="9.053100E-07"
        izz="4.486856E-05" />
    </inertial>
    <visual>
      <origin
        xyz="0 0 0"
        rpy="0 0 0" />
      <geometry>
        <mesh
          filename="/home/master/Bureau/BD-5/description/BD-5/meshes/HIP_RIGHT.STL" />
      </geometry>
      <material
        name="">
        <color
          rgba="0.25098 0.25098 0.25098 1" />
      </material>
    </visual>
    <collision>
      <origin
        xyz="0 0 0"
        rpy="0 0 0" />
      <geometry>
        <mesh
          filename="/home/master/Bureau/BD-5/description/BD-5/meshes/HIP_RIGHT.STL" />
      </geometry>
    </collision>
  </link>
  <joint
    name="right_hip_yaw"
    type="revolute">
    <origin
      xyz="0 -0.01425 -0.0436"
      rpy="0 0 0" />
    <parent
      link="BODY" />
    <child
      link="HIP_RIGHT" />
    <axis
      xyz="0 0 1" />
    <limit
      lower="-0.37899"
      upper="0.37899"
      effort="41"
      velocity="4.8171" />
    <dynamics
      damping="1.084"
      friction="0.03" />
    <safety_controller
      k_position="21.1"
      k_velocity="0" />
  </joint>
  <link
    name="HIP_R_RIGHT">
    <inertial>
      <origin
        xyz="0 0 -25.15E-03"
        rpy="0 0 0" />
      <mass
        value="0.018" />
      <inertia
        ixx="5.92983E-06"
        ixy="-2.00000E-11"
        ixz="0.0"
        iyy="6.25751E-06"
        iyz="0.0"
        izz="7.87081E-06" />
    </inertial>
    <visual>
      <origin
        xyz="0 0 0"
        rpy="0 0 0" />
      <geometry>
        <mesh
          filename="/home/master/Bureau/BD-5/description/BD-5/meshes/HIP_R_RIGHT.STL" />
      </geometry>
      <material
        name="">
        <color
          rgba="0.25098 0.25098 0.25098 1" />
      </material>
    </visual>
    <collision>
      <origin
        xyz="0 0 0"
        rpy="0 0 0" />
      <geometry>
        <mesh
          filename="/home/master/Bureau/BD-5/description/BD-5/meshes/HIP_R_RIGHT.STL" />
      </geometry>
    </collision>
  </link>
  <joint
    name="right_hip_roll"
    type="revolute">
    <origin
      xyz="0 -0.05925 0.01275"
      rpy="0 0 0" />
    <parent
      link="HIP_RIGHT" />
    <child
      link="HIP_R_RIGHT" />
    <axis
      xyz="1 0 0" />
    <limit
      lower="-1.8827"
      upper="0.38819"
      effort="41"
      velocity="4.8171" />
    <dynamics
      damping="1.084"
      friction="0.03" />
    <safety_controller
      k_position="21.1"
      k_velocity="0" />
  </joint>
  <link
    name="THIGH_RIGHT">
    <inertial>
      <origin
        xyz="0 2.15E-03 -35.25E-03"
        rpy="0 0 0" />
      <mass
        value="0.174" />
      <inertia
        ixx="1.1144779E-04"
        ixy="0.0"
        ixz="-5.9978000E-07"
        iyy="9.3367670E-05"
        iyz="0.0"
        izz="5.1193580E-05" />
    </inertial>
    <visual>
      <origin
        xyz="0 0 0"
        rpy="0 0 0" />
      <geometry>
        <mesh
          filename="/home/master/Bureau/BD-5/description/BD-5/meshes/THIGH_RIGHT.STL" />
      </geometry>
      <material
        name="">
        <color
          rgba="0.25098 0.25098 0.25098 1" />
      </material>
    </visual>
    <collision>
      <origin
        xyz="0 0 0"
        rpy="0 0 0" />
      <geometry>
        <mesh
          filename="/home/master/Bureau/BD-5/description/BD-5/meshes/THIGH_RIGHT.STL" />
      </geometry>
    </collision>
  </link>
  <joint
    name="right_hip_pitch"
    type="revolute">
    <origin
      xyz="0 0 -0.05"
      rpy="0 0 0" />
    <parent
      link="HIP_R_RIGHT" />
    <child
      link="THIGH_RIGHT" />
    <axis
      xyz="0 1 0" />
    <limit
      lower="-1.7492"
      upper="1.7492"
      effort="41"
      velocity="4.8171" />
    <dynamics
      damping="1.084"
      friction="0.03" />
    <safety_controller
      k_position="21.1"
      k_velocity="0" />
  </joint>
  <link
    name="CALF_RIGHT">
    <inertial>
      <origin
        xyz="0.34E-03 1.91E-03 -50.36E-03"
        rpy="0 0 0" />
      <mass
        value="0.098" />
      <inertia
        ixx="4.467074E-05"
        ixy="-2.144200E-06"
        ixz="1.998000E-07"
        iyy="3.067445E-05"
        iyz="3.182100E-06"
        izz="3.166172E-05" />
    </inertial>
    <visual>
      <origin
        xyz="0 0 0"
        rpy="0 0 0" />
      <geometry>
        <mesh
          filename="/home/master/Bureau/BD-5/description/BD-5/meshes/CALF_RIGHT.STL" />
      </geometry>
      <material
        name="">
        <color
          rgba="0.25098 0.25098 0.25098 1" />
      </material>
    </visual>
    <collision>
      <origin
        xyz="0 0 0"
        rpy="0 0 0" />
      <geometry>
        <mesh
          filename="/home/master/Bureau/BD-5/description/BD-5/meshes/CALF_RIGHT.STL" />
      </geometry>
    </collision>
  </link>
  <joint
    name="right_knee"
    type="revolute">
    <origin
      xyz="0 0 -0.0705"
      rpy="0 0 0" />
    <parent
      link="THIGH_RIGHT" />
    <child
      link="CALF_RIGHT" />
    <axis
      xyz="0 -1 0" />
    <limit
      lower="0"
      upper="2.3829"
      effort="41"
      velocity="4.8171" />
    <dynamics
      damping="1.084"
      friction="0.03" />
    <safety_controller
      k_position="21.1"
      k_velocity="0" />
  </joint>
  <link
    name="FOOT_RIGHT">
    <inertial>
      <origin
        xyz="0 0 -33.34E-03"
        rpy="0 0 0" />
      <mass
        value="0.032" />
      <inertia
        ixx="6.903700E-06"
        ixy="0.0"
        ixz="0.0"
        iyy="3.164244E-05"
        iyz="0.0"
        izz="3.174429E-05" />
    </inertial>
    <visual>
      <origin
        xyz="0 0 0"
        rpy="0 0 0" />
      <geometry>
        <mesh
          filename="/home/master/Bureau/BD-5/description/BD-5/meshes/FOOT_RIGHT.STL" />
      </geometry>
      <material
        name="">
        <color
          rgba="0.9098 0.44314 0.031373 1" />
      </material>
    </visual>
    <collision>
      <origin
        xyz="0 0 0"
        rpy="0 0 0" />
      <geometry>
        <mesh
          filename="/home/master/Bureau/BD-5/description/BD-5/meshes/FOOT_RIGHT.STL" />
      </geometry>
    </collision>
  </link>
  <joint
    name="right_ankle"
    type="revolute">
    <origin
      xyz="0 0 -0.07064"
      rpy="0 0 0" />
    <parent
      link="CALF_RIGHT" />
    <child
      link="FOOT_RIGHT" />
    <axis
      xyz="0 1 0" />
    <limit
      lower="-1.8873"
      upper="1.8873"
      effort="41"
      velocity="4.8171" />
    <dynamics
      damping="1.084"
      friction="0.03" />
    <safety_controller
      k_position="21.1"
      k_velocity="0" />
  </joint>
</robot>
