<mujoco model="BD-5">
  <option iterations="50" timestep="0.001" solver="PGS" gravity="0 0 -9.81" />

  <compiler angle="radian" meshdir="meshes" eulerseq="zyx" autolimits="true" />

  <default>
    <joint limited="true" damping="1.084" armature="0.045" frictionloss="0.03" />
    <geom condim="4" contype="1" conaffinity="15" friction="0.9 0.2 0.2" solref="0.001 2" />
    <motor ctrllimited="true" />
    <equality solref="0.001 2" />
    <default class="visualgeom">
      <geom material="visualgeom" condim="1" contype="0" conaffinity="0" />
    </default>
  </default>

  <asset>
    <mesh name="BODY" file="BODY.STL" />
    <mesh name="NECK" file="NECK.STL" />
    <mesh name="HEAD" file="HEAD.STL" />
    <mesh name="HIP_LEFT" file="HIP_LEFT.STL" />
    <mesh name="HIP_R_LEFT" file="HIP_R_LEFT.STL" />
    <mesh name="THIGH_LEFT" file="THIGH_LEFT.STL" />
    <mesh name="CALF_LEFT" file="CALF_LEFT.STL" />
    <mesh name="FOOT_LEFT" file="FOOT_LEFT.STL" />
    <mesh name="HIP_RIGHT" file="HIP_RIGHT.STL" />
    <mesh name="HIP_R_RIGHT" file="HIP_R_RIGHT.STL" />
    <mesh name="THIGH_RIGHT" file="THIGH_RIGHT.STL" />
    <mesh name="CALF_RIGHT" file="CALF_RIGHT.STL" />
    <mesh name="FOOT_RIGHT" file="FOOT_RIGHT.STL" />
    <texture name="texplane" type="2d" builtin="checker" rgb1=".0 .0 .0" rgb2=".8 .8 .8" width="100" height="100" />
    <material name="matplane" reflectance="0." texture="texplane" texrepeat="1 1" texuniform="true" />
    <material name="visualgeom" rgba="0.5 0.9 0.2 1" />
  </asset>

  <worldbody>
    <light directional="true" diffuse="0.4 0.4 0.4" specular="0.1 0.1 0.1" pos="0 0 5.0" dir="0 0 -1" castshadow="false" />
    <light directional="true" diffuse="0.6 0.6 0.6" specular="0.2 0.2 0.2" pos="0 0 4" dir="0 0 -1" />
    <geom name="ground" type="plane" pos="0 0 0" size="100 100 0.001" quat="1 0 0 0" material="matplane" condim="3" conaffinity="15" />
    <camera name="fixed" pos="0 -3.0 0.8170777382037414" xyaxes="1 0 0 0 0 1" />
    <camera name="track" mode="trackcom" pos="0 -3.0 0.8170777382037414" xyaxes="1 0 0 0 0 1" />
    <body name="root" pos="0 0 0.3170777382037414" quat="1 0 0 0">
      <freejoint name="root" />
      <site name="imu" size="0.01" pos="0 0 0" />
      <geom type="mesh" rgba="0.9098 0.44314 0.031373 1" mesh="BODY" contype="1" conaffinity="0" density="0" group="1" class="visualgeom" />
      <geom type="mesh" rgba="0.9098 0.44314 0.031373 1" mesh="BODY" />
      <geom pos="0.039 -0.0017032 0.06245" quat="0.965768 0 -0.259409 0" type="mesh" rgba="0.25098 0.25098 0.25098 1" mesh="NECK" contype="1" conaffinity="0" density="0" group="1" class="visualgeom" />
      <geom type="mesh" rgba="0.25098 0.25098 0.25098 1" mesh="NECK" pos="0.039 -0.0017032 0.06245" quat="0.965768 0 -0.259409 0" />
      <geom pos="-0.00208669 -0.0017032 0.133414" quat="0.999999 0 0.00161 0" type="mesh" rgba="0.9098 0.44314 0.031373 1" mesh="HEAD" contype="1" conaffinity="0" density="0" group="1" class="visualgeom" />
      <geom type="mesh" rgba="0.9098 0.44314 0.031373 1" mesh="HEAD" pos="-0.00208669 -0.0017032 0.133414" quat="0.999999 0 0.00161 0" />
      <body name="HIP_LEFT" pos="0 0.01425 -0.0436">
        <inertial pos="0.00185 0.05284 0.02786" quat="0.460341 -0.108037 -0.0721488 0.878185" mass="0.101" diaginertia="4.55664e-05 4.08892e-05 2.89285e-05" />
        <joint name="left_hip_yaw" pos="0 0 0" axis="0 0 1" range="-0.37899 0.37899" actuatorfrcrange="-41 41" damping="1.084" armature="0.045" frictionloss="0.03" />
        <geom type="mesh" rgba="0.25098 0.25098 0.25098 1" mesh="HIP_LEFT" contype="1" conaffinity="0" density="0" group="1" class="visualgeom" />
        <geom type="mesh" rgba="0.25098 0.25098 0.25098 1" mesh="HIP_LEFT" />
        <body name="HIP_R_LEFT" pos="0 0.05925 0.01275">
          <inertial pos="0 0 -0.02515" quat="0.500015 0.499985 -0.500015 0.499985" mass="0.018" diaginertia="7.87081e-06 6.25751e-06 5.92983e-06" />
          <joint name="left_hip_roll" pos="0 0 0" axis="-1 0 0" range="-1.8827 0.38819" actuatorfrcrange="-41 41" damping="1.084" armature="0.045" frictionloss="0.03" />
          <geom type="mesh" rgba="0.25098 0.25098 0.25098 1" mesh="HIP_R_LEFT" contype="1" conaffinity="0" density="0" group="1" class="visualgeom" />
          <geom type="mesh" rgba="0.25098 0.25098 0.25098 1" mesh="HIP_R_LEFT" />
          <body name="THIGH_LEFT" pos="0 0 -0.05">
            <inertial pos="0 0.00215 -0.03525" quat="0.999988 0 0.0049764 0" mass="0.174" diaginertia="0.000111454 9.33677e-05 5.11876e-05" />
            <joint name="left_hip_pitch" pos="0 0 0" axis="0 1 0" range="-1.7492 1.7492" actuatorfrcrange="-41 41" damping="1.084" armature="0.045" frictionloss="0.03" />
            <geom type="mesh" rgba="0.25098 0.25098 0.25098 1" mesh="THIGH_LEFT" contype="1" conaffinity="0" density="0" group="1" class="visualgeom" />
            <geom type="mesh" rgba="0.25098 0.25098 0.25098 1" mesh="THIGH_LEFT" />
            <body name="CALF_LEFT" pos="0 0 -0.0705">
              <inertial pos="0.00034 0.00191 -0.05036" quat="0.900306 0.428328 -0.0231046 -0.0738207" mass="0.098" diaginertia="4.49978e-05 3.42466e-05 2.77625e-05" />
              <joint name="left_knee" pos="0 0 0" axis="0 -1 0" range="0 2.3829" actuatorfrcrange="-41 41" damping="1.084" armature="0.045" frictionloss="0.03" />
              <geom type="mesh" rgba="0.25098 0.25098 0.25098 1" mesh="CALF_LEFT" contype="1" conaffinity="0" density="0" group="1" class="visualgeom" />
              <geom type="mesh" rgba="0.25098 0.25098 0.25098 1" mesh="CALF_LEFT" />
              <body name="FOOT_LEFT" pos="0 0 -0.07064">
                <inertial pos="0 0 -0.03334" quat="0 0.707107 0 0.707107" mass="0.032" diaginertia="3.17443e-05 3.16424e-05 6.9037e-06" />
                <joint name="left_ankle" pos="0 0 0" axis="0 1 0" range="-1.8873 1.8873" actuatorfrcrange="-41 41" damping="1.084" armature="0.045" frictionloss="0.03" />
                <geom type="mesh" rgba="0.9098 0.44314 0.031373 1" mesh="FOOT_LEFT" contype="1" conaffinity="0" density="0" group="1" class="visualgeom" />
                <geom type="mesh" rgba="0.9098 0.44314 0.031373 1" mesh="FOOT_LEFT" />
              </body>
            </body>
          </body>
        </body>
      </body>
      <body name="HIP_RIGHT" pos="0 -0.01425 -0.0436">
        <inertial pos="0.00185 -0.0535 0.02786" quat="0.649192 0.572543 -0.368859 0.338655" mass="0.101" diaginertia="4.61603e-05 4.12116e-05 2.96353e-05" />
        <joint name="right_hip_yaw" pos="0 0 0" axis="0 0 1" range="-0.37899 0.37899" actuatorfrcrange="-41 41" damping="1.084" armature="0.045" frictionloss="0.03" />
        <geom type="mesh" rgba="0.25098 0.25098 0.25098 1" mesh="HIP_RIGHT" contype="1" conaffinity="0" density="0" group="1" class="visualgeom" />
        <geom type="mesh" rgba="0.25098 0.25098 0.25098 1" mesh="HIP_RIGHT" />
        <body name="HIP_R_RIGHT" pos="0 -0.05925 0.01275">
          <inertial pos="0 0 -0.02515" quat="-2.15792e-05 0.707107 2.15792e-05 0.707107" mass="0.018" diaginertia="7.87081e-06 6.25751e-06 5.92983e-06" />
          <joint name="right_hip_roll" pos="0 0 0" axis="1 0 0" range="-1.8827 0.38819" actuatorfrcrange="-41 41" damping="1.084" armature="0.045" frictionloss="0.03" />
          <geom type="mesh" rgba="0.25098 0.25098 0.25098 1" mesh="HIP_R_RIGHT" contype="1" conaffinity="0" density="0" group="1" class="visualgeom" />
          <geom type="mesh" rgba="0.25098 0.25098 0.25098 1" mesh="HIP_R_RIGHT" />
          <body name="THIGH_RIGHT" pos="0 0 -0.05">
            <inertial pos="0 0.00215 -0.03525" quat="0.999988 0 0.0049764 0" mass="0.174" diaginertia="0.000111454 9.33677e-05 5.11876e-05" />
            <joint name="right_hip_pitch" pos="0 0 0" axis="0 1 0" range="-1.7492 1.7492" actuatorfrcrange="-41 41" damping="1.084" armature="0.045" frictionloss="0.03" />
            <geom type="mesh" rgba="0.25098 0.25098 0.25098 1" mesh="THIGH_RIGHT" contype="1" conaffinity="0" density="0" group="1" class="visualgeom" />
            <geom type="mesh" rgba="0.25098 0.25098 0.25098 1" mesh="THIGH_RIGHT" />
            <body name="CALF_RIGHT" pos="0 0 -0.0705">
              <inertial pos="0.00034 0.00191 -0.05036" quat="0.900306 0.428328 -0.0231046 -0.0738207" mass="0.098" diaginertia="4.49978e-05 3.42466e-05 2.77625e-05" />
              <joint name="right_knee" pos="0 0 0" axis="0 -1 0" range="0 2.3829" actuatorfrcrange="-41 41" damping="1.084" armature="0.045" frictionloss="0.03" />
              <geom type="mesh" rgba="0.25098 0.25098 0.25098 1" mesh="CALF_RIGHT" contype="1" conaffinity="0" density="0" group="1" class="visualgeom" />
              <geom type="mesh" rgba="0.25098 0.25098 0.25098 1" mesh="CALF_RIGHT" />
              <body name="FOOT_RIGHT" pos="0 0 -0.07064">
                <inertial pos="0 0 -0.03334" quat="0 0.707107 0 0.707107" mass="0.032" diaginertia="3.17443e-05 3.16424e-05 6.9037e-06" />
                <joint name="right_ankle" pos="0 0 0" axis="0 1 0" range="-1.8873 1.8873" actuatorfrcrange="-41 41" damping="1.084" armature="0.045" frictionloss="0.03" />
                <geom type="mesh" rgba="0.9098 0.44314 0.031373 1" mesh="FOOT_RIGHT" contype="1" conaffinity="0" density="0" group="1" class="visualgeom" />
                <geom type="mesh" rgba="0.9098 0.44314 0.031373 1" mesh="FOOT_RIGHT" />
              </body>
            </body>
          </body>
        </body>
      </body>
    </body>
  </worldbody>

  <actuator>
    <motor name="left_hip_yaw" joint="left_hip_yaw" ctrllimited="true" ctrlrange="-41 41" gear="1" />
    <motor name="left_hip_roll" joint="left_hip_roll" ctrllimited="true" ctrlrange="-41 41" gear="1" />
    <motor name="left_hip_pitch" joint="left_hip_pitch" ctrllimited="true" ctrlrange="-41 41" gear="1" />
    <motor name="left_knee" joint="left_knee" ctrllimited="true" ctrlrange="-41 41" gear="1" />
    <motor name="left_ankle" joint="left_ankle" ctrllimited="true" ctrlrange="-41 41" gear="1" />
    <motor name="right_hip_yaw" joint="right_hip_yaw" ctrllimited="true" ctrlrange="-41 41" gear="1" />
    <motor name="right_hip_roll" joint="right_hip_roll" ctrllimited="true" ctrlrange="-41 41" gear="1" />
    <motor name="right_hip_pitch" joint="right_hip_pitch" ctrllimited="true" ctrlrange="-41 41" gear="1" />
    <motor name="right_knee" joint="right_knee" ctrllimited="true" ctrlrange="-41 41" gear="1" />
    <motor name="right_ankle" joint="right_ankle" ctrllimited="true" ctrlrange="-41 41" gear="1" />
  </actuator>

  <sensor>
    <actuatorpos name="left_hip_yaw_p" actuator="left_hip_yaw" />
    <actuatorvel name="left_hip_yaw_v" actuator="left_hip_yaw" />
    <actuatorfrc name="left_hip_yaw_f" actuator="left_hip_yaw" noise="0.001" />
    <actuatorpos name="left_hip_roll_p" actuator="left_hip_roll" />
    <actuatorvel name="left_hip_roll_v" actuator="left_hip_roll" />
    <actuatorfrc name="left_hip_roll_f" actuator="left_hip_roll" noise="0.001" />
    <actuatorpos name="left_hip_pitch_p" actuator="left_hip_pitch" />
    <actuatorvel name="left_hip_pitch_v" actuator="left_hip_pitch" />
    <actuatorfrc name="left_hip_pitch_f" actuator="left_hip_pitch" noise="0.001" />
    <actuatorpos name="left_knee_p" actuator="left_knee" />
    <actuatorvel name="left_knee_v" actuator="left_knee" />
    <actuatorfrc name="left_knee_f" actuator="left_knee" noise="0.001" />
    <actuatorpos name="left_ankle_p" actuator="left_ankle" />
    <actuatorvel name="left_ankle_v" actuator="left_ankle" />
    <actuatorfrc name="left_ankle_f" actuator="left_ankle" noise="0.001" />
    <actuatorpos name="right_hip_yaw_p" actuator="right_hip_yaw" />
    <actuatorvel name="right_hip_yaw_v" actuator="right_hip_yaw" />
    <actuatorfrc name="right_hip_yaw_f" actuator="right_hip_yaw" noise="0.001" />
    <actuatorpos name="right_hip_roll_p" actuator="right_hip_roll" />
    <actuatorvel name="right_hip_roll_v" actuator="right_hip_roll" />
    <actuatorfrc name="right_hip_roll_f" actuator="right_hip_roll" noise="0.001" />
    <actuatorpos name="right_hip_pitch_p" actuator="right_hip_pitch" />
    <actuatorvel name="right_hip_pitch_v" actuator="right_hip_pitch" />
    <actuatorfrc name="right_hip_pitch_f" actuator="right_hip_pitch" noise="0.001" />
    <actuatorpos name="right_knee_p" actuator="right_knee" />
    <actuatorvel name="right_knee_v" actuator="right_knee" />
    <actuatorfrc name="right_knee_f" actuator="right_knee" noise="0.001" />
    <actuatorpos name="right_ankle_p" actuator="right_ankle" />
    <actuatorvel name="right_ankle_v" actuator="right_ankle" />
    <actuatorfrc name="right_ankle_f" actuator="right_ankle" noise="0.001" />
    <framequat name="orientation" objtype="site" noise="0.001" objname="imu" />
    <gyro name="angular-velocity" site="imu" noise="0.005" cutoff="34.9" />
  </sensor>
</mujoco>
