<mujoco model="BD-5">

  <compiler angle="radian" autolimits="true"/>
  <option iterations="1" ls_iterations="5" timestep="0.002" integrator="Euler" gravity="0 0 -9.81">
    <flag eulerdamp="disable"/>
  </option>

  <default>
    <geom condim="1" contype="0" conaffinity="0"/>
    <site size="0.01" rgba="1 0 0 1" group="4"/>
    <joint limited="true" damping="1.084" armature="0.045" actuatorfrcrange="-4.1 4.1" frictionloss="0.03"/>
    <position inheritrange="1.0" kp="21.1" kv="0" forcerange="-4.1 4.1"/>
    <equality solref="0.001 2"/>
  </default>

  <asset>
    <mesh name="BODY" file="assets/BODY.STL" maxhullvert="20"/>
    <mesh name="NECK" file="assets/NECK.STL" maxhullvert="20"/>
    <mesh name="HEAD" file="assets/HEAD.STL" maxhullvert="20"/>
    <mesh name="HIP_LEFT" file="assets/HIP_LEFT.STL" maxhullvert="20"/>
    <mesh name="HIP_R_LEFT" file="assets/HIP_R_LEFT.STL" maxhullvert="20"/>
    <mesh name="THIGH_LEFT" file="assets/THIGH_LEFT.STL" maxhullvert="20"/>
    <mesh name="CALF_LEFT" file="assets/CALF_LEFT.STL" maxhullvert="20"/>
    <mesh name="FOOT_LEFT" file="assets/FOOT_LEFT.STL" maxhullvert="20"/>
    <mesh name="HIP_RIGHT" file="assets/HIP_RIGHT.STL" maxhullvert="20"/>
    <mesh name="HIP_R_RIGHT" file="assets/HIP_R_RIGHT.STL" maxhullvert="20"/>
    <mesh name="THIGH_RIGHT" file="assets/THIGH_RIGHT.STL" maxhullvert="20"/>
    <mesh name="CALF_RIGHT" file="assets/CALF_RIGHT.STL" maxhullvert="20"/>
    <mesh name="FOOT_RIGHT" file="assets/FOOT_RIGHT.STL" maxhullvert="20"/>
  </asset>

  <worldbody>
    <body name="root" pos="0 0 0.3170777382037414" quat="1 0 0 0">
      <freejoint name="root" />
      <site name="imu" pos="0 0 0" />
      <camera name="front" mode="trackcom" pos="0 -3.0 0.8170777382037414" xyaxes="1 0 0 0 0 1" />
      <camera name="track" mode="trackcom" pos="0 -3.0 0.8170777382037414" xyaxes="1 0 0 0 0 1" />
      <geom type="mesh" rgba="0.9098 0.44314 0.031373 1" mesh="BODY" />
      <geom type="mesh" rgba="0.25098 0.25098 0.25098 1" mesh="NECK" pos="0.039 -0.0017032 0.06245" quat="0.965768 0 -0.259409 0" />
      <geom type="mesh" rgba="0.9098 0.44314 0.031373 1" mesh="HEAD" pos="-0.00208669 -0.0017032 0.133414" quat="0.999999 0 0.00161 0" />
      <body name="HIP_LEFT" pos="0 0.01425 -0.0436">
        <inertial pos="0.00185 0.05284 0.02786" quat="0.460341 -0.108037 -0.0721488 0.878185" mass="0.101" diaginertia="4.55664e-05 4.08892e-05 2.89285e-05" />
        <joint name="left_hip_yaw" pos="0 0 0" axis="0 0 1" range="-0.37899 0.37899"/>
        <geom type="mesh" rgba="0.25098 0.25098 0.25098 1" mesh="HIP_LEFT" />
        <body name="HIP_R_LEFT" pos="0 0.05925 0.01275">
          <inertial pos="0 0 -0.02515" quat="0.500015 0.499985 -0.500015 0.499985" mass="0.018" diaginertia="7.87081e-06 6.25751e-06 5.92983e-06" />
          <joint name="left_hip_roll" pos="0 0 0" axis="-1 0 0" range="-1.8827 0.38819" />
          <geom type="mesh" rgba="0.25098 0.25098 0.25098 1" mesh="HIP_R_LEFT" />
          <body name="THIGH_LEFT" pos="0 0 -0.05">
            <inertial pos="0 0.00215 -0.03525" quat="0.999988 0 0.0049764 0" mass="0.174" diaginertia="0.000111454 9.33677e-05 5.11876e-05" />
            <joint name="left_hip_pitch" pos="0 0 0" axis="0 1 0" range="-1.7492 1.7492" />
            <geom type="mesh" rgba="0.25098 0.25098 0.25098 1" mesh="THIGH_LEFT" />
            <body name="CALF_LEFT" pos="0 0 -0.0705">
              <inertial pos="0.00034 0.00191 -0.05036" quat="0.900306 0.428328 -0.0231046 -0.0738207" mass="0.098" diaginertia="4.49978e-05 3.42466e-05 2.77625e-05" />
              <joint name="left_knee" pos="0 0 0" axis="0 -1 0" range="0 2.3829" />
              <geom type="mesh" rgba="0.25098 0.25098 0.25098 1" mesh="CALF_LEFT" />
              <body name="FOOT_LEFT" pos="0 0 -0.07064">
                <inertial pos="0 0 -0.03334" quat="0 0.707107 0 0.707107" mass="0.032" diaginertia="3.17443e-05 3.16424e-05 6.9037e-06" />
                <joint name="left_ankle" pos="0 0 0" axis="0 1 0" range="-1.8873 1.8873" />
                <geom type="mesh" rgba="0.9098 0.44314 0.031373 1" mesh="FOOT_LEFT" contype="0" conaffinity="1" friction="0.8 0.02 0.01"/>
              </body>
            </body>
          </body>
        </body>
      </body>
      <body name="HIP_RIGHT" pos="0 -0.01425 -0.0436">
        <inertial pos="0.00185 -0.0535 0.02786" quat="0.649192 0.572543 -0.368859 0.338655" mass="0.101" diaginertia="4.61603e-05 4.12116e-05 2.96353e-05" />
        <joint name="right_hip_yaw" pos="0 0 0" axis="0 0 1" range="-0.37899 0.37899" />
        <geom type="mesh" rgba="0.25098 0.25098 0.25098 1" mesh="HIP_RIGHT" />
        <body name="HIP_R_RIGHT" pos="0 -0.05925 0.01275">
          <inertial pos="0 0 -0.02515" quat="-2.15792e-05 0.707107 2.15792e-05 0.707107" mass="0.018" diaginertia="7.87081e-06 6.25751e-06 5.92983e-06" />
          <joint name="right_hip_roll" pos="0 0 0" axis="1 0 0" range="-1.8827 0.38819" />
          <geom type="mesh" rgba="0.25098 0.25098 0.25098 1" mesh="HIP_R_RIGHT" />
          <body name="THIGH_RIGHT" pos="0 0 -0.05">
            <inertial pos="0 0.00215 -0.03525" quat="0.999988 0 0.0049764 0" mass="0.174" diaginertia="0.000111454 9.33677e-05 5.11876e-05" />
            <joint name="right_hip_pitch" pos="0 0 0" axis="0 1 0" range="-1.7492 1.7492" />
            <geom type="mesh" rgba="0.25098 0.25098 0.25098 1" mesh="THIGH_RIGHT" />
            <body name="CALF_RIGHT" pos="0 0 -0.0705">
              <inertial pos="0.00034 0.00191 -0.05036" quat="0.900306 0.428328 -0.0231046 -0.0738207" mass="0.098" diaginertia="4.49978e-05 3.42466e-05 2.77625e-05" />
              <joint name="right_knee" pos="0 0 0" axis="0 -1 0" range="0 2.3829" />
              <geom type="mesh" rgba="0.25098 0.25098 0.25098 1" mesh="CALF_RIGHT" />
              <body name="FOOT_RIGHT" pos="0 0 -0.07064">
                <inertial pos="0 0 -0.03334" quat="0 0.707107 0 0.707107" mass="0.032" diaginertia="3.17443e-05 3.16424e-05 6.9037e-06" />
                <joint name="right_ankle" pos="0 0 0" axis="0 1 0" range="-1.8873 1.8873" />
                <geom type="mesh" rgba="0.9098 0.44314 0.031373 1" mesh="FOOT_RIGHT" contype="0" conaffinity="1" friction="0.8 0.02 0.01"/>
              </body>
            </body>
          </body>
        </body>
      </body>
    </body>
  </worldbody>

  <actuator>
    <position name="left_hip_yaw" joint="left_hip_yaw" inheritrange="1"/>
    <position name="left_hip_roll" joint="left_hip_roll" inheritrange="1"/>
    <position name="left_hip_pitch" joint="left_hip_pitch" inheritrange="1"/>
    <position name="left_knee" joint="left_knee" inheritrange="1"/>
    <position name="left_ankle" joint="left_ankle" inheritrange="1"/>
    <position name="right_hip_yaw" joint="right_hip_yaw" inheritrange="1"/>
    <position name="right_hip_roll" joint="right_hip_roll" inheritrange="1"/>
    <position name="right_hip_pitch" joint="right_hip_pitch" inheritrange="1"/>
    <position name="right_knee" joint="right_knee" inheritrange="1"/>
    <position name="right_ankle" joint="right_ankle" inheritrange="1"/>
  </actuator>

  <sensor>
    <gyro site="imu" name="gyro"/>
    <velocimeter site="imu" name="local_linvel"/>
    <accelerometer site="imu" name="accelerometer"/>
    <framepos objtype="site" objname="imu" name="position"/>
    <framezaxis objtype="site" objname="imu" name="upvector"/>
    <framexaxis objtype="site" objname="imu" name="forwardvector"/>
    <framelinvel objtype="site" objname="imu" name="global_linvel"/>
    <frameangvel objtype="site" objname="imu" name="global_angvel"/>
    <framequat objtype="site" objname="imu" name="orientation"/>
    <!--framepos objtype="site" objname="FOOT_LEFT" name="left_foot_pos"/>
    <framepos objtype="site" objname="FOOT_RIGHT" name="right_foot_pos"/>
    <framelinvel objtype="site" objname="FOOT_RIGHT" name="right_foot_global_linvel"/>
    <framelinvel objtype="site" objname="FOOT_LEFT" name="left_foot_global_linvel"/-->
  </sensor>
</mujoco>
